Workbook

Sheet 說明
A1: Bizlution FMS 第一階段後端開發 — 工作分解結構（WBS）
A3: 文件版本 | B3: v1.0（與《FMS_Phase1_後端工程開發規格書.docx》同一基準）
A4: 建立日期 | B4: 2026-07-28
A5: 專案期間 | B5: 2026-08-03 ～ 2027-01-29（13 個 Sprint，每 Sprint 2 週，共 26 週；S9–S10 對標補強、S11–S12 完成全部 P2）
A6: 任務總數 | B6: ="共 "&COUNTA(WBS!A2:A200)&" 項任務" -> 共 137 項任務
A7: 估算總量 | B7: ="合計 "&TEXT(SUMIF(WBS!$A$2:$A$400,"<>",WBS!$H$2:$H$400),"0.0")&" 人日（不含管理緩衝）" -> 合計 494.0 人日（不含管理緩衝）
A9: 工作表導覽
A10: WBS | B10: 主工作表：任務分解、角色、人日估算、依賴、計畫起訖、狀態、驗收條件
A11: Sprint 摘要 | B11: 每個 Sprint 的工作量、任務數、日程與主題（全部為公式，隨 WBS 變動）
A12: 資源負載 | B12: 角色 × Sprint 的人日矩陣，附產能比對與負載率
A13: 里程碑 | B13: 8 個里程碑與其通過條件（Gate Criteria）
A14: 假設與風險 | B14: 估算假設、人力配置、主要風險與應對
A16: 填寫說明
A17: 需要你填的欄位 | B17: WBS 工作表的 K 欄（狀態）與 L 欄（完成 %）；黃色底色即為輸入格
A18: 狀態可選值 | B18: 未開始 / 進行中 / 已完成 / 阻塞 / 已取消（已設下拉選單）
A19: 完成 % 格式 | B19: 請輸入 0～1 的小數（例如 0.3 顯示為 30%），不要輸入 30
A20: 估算欄（G 欄） | B20: 藍色字為可調整的估算輸入值；改動後所有摘要與負載會自動重算
A21: 日期欄（I、J 欄） | B21: 由 Sprint 起訖日帶入，屬計畫值；實際排程請於專案管理工具追蹤
A23: 範例列（示意格式，非實際任務）
A24: WBS | B24: Sprint | C24: 模組 | D24: 任務 | E24: 主要角色 | F24: 人日 | G24: 狀態 | H24: 完成 %
A25: 5.2 | B25: S4 | C25: 工單 | D25: 狀態機服務層 | E25: Tech Lead | F25: 6 | G25: 進行中 | H25: 0.3
A27: 色彩圖例
A28: 輸入格（請填寫）
A29: 估算輸入值（可調整）
A30: 公式計算結果
A31: 跨表引用

Sheet WBS
A1: WBS | B1: Sprint | C1: 階段主題 | D1: 模組 | E1: 任務名稱 | F1: 交付物／說明 | G1: 主要角色 | H1: 估算(人日) | I1: 依賴 WBS | J1: 計畫開始 | K1: 計畫結束 | L1: 狀態 | M1: 完成 % | N1: 加權完成(人日) | O1: 驗收條件
A2: 1.1 | B2: S0 | C2: 環境與基礎建設 | D2: 基礎建設 | E2: 建立 Git repo 與分支策略 | F2: trunk-based + PR 檢查；CODEOWNERS 依模組劃分 | G2: DevOps | H2: 1 | J2: 46237 | K2: 46248 | L2: 未開始 | M2: 0 | N2: =H2*M2 -> 0 | O2: PR 未過 CI 無法合併
A3: 1.2 | B3: S0 | C3: 環境與基礎建設 | D3: 基礎建設 | E3: 建立 CI 流程 | F3: lint（ruff）、型別（mypy）、pytest、SQL parser 驗證、import-linter 模組邊界檢查 | G3: DevOps | H3: 3 | I3: 1.1 | J3: 46237 | K3: 46248 | L3: 未開始 | M3: 0 | N3: =H3*M3 -> 0 | O3: 任一檢查失敗即阻擋合併
A4: 1.3 | B4: S0 | C4: 環境與基礎建設 | D4: 基礎建設 | E4: 建立自建 PostgreSQL 環境（Docker） | F4: docker-compose：PG16＋Redis＋MinIO＋Mailpit＋MQTT；三角色分離（fms_owner／fms_app／fms_readonly） | G4: DevOps | H4: 3 | J4: 46237 | K4: 46248 | L4: 未開始 | M4: 0 | N4: =H4*M4 -> 0 | O4: make fresh 可從零建出可用環境；make check-rls 全綠
A5: 1.4 | B5: S0 | C5: 環境與基礎建設 | D5: 基礎建設 | E5: Migration 執行機制 | F5: psql ON_ERROR_STOP 腳本＋版本紀錄表；固定順序（005/006 補外鍵、008 先於工單、013 最後） | G5: DBA / Data | H5: 2 | I5: 1.3 | J5: 46237 | K5: 46248 | L5: 未開始 | M5: 0 | N5: =H5*M5 -> 0 | O5: dev 可一鍵重建全庫且順序不可誤用
A6: 1.5 | B6: S0 | C6: 環境與基礎建設 | D6: 基礎建設 | E6: 開發環境文件與 CI 整合 | F6: README、Makefile、migrate/smoke-test 腳本；CI 以同一批腳本執行 | G6: DevOps | H6: 2.5 | I6: 1.4 | J6: 46237 | K6: 46248 | L6: 未開始 | M6: 0 | N6: =H6*M6 -> 0 | O6: CI 與本機使用同一組腳本，行為一致
A7: 1.6 | B7: S0 | C7: 環境與基礎建設 | D7: 基礎建設 | E7: FastAPI 專案骨架與模組目錄 | F7: 10 個模組目錄、settings、DI 容器、統一 Problem Details 例外處理 | G7: Tech Lead | H7: 3 | I7: 1.1 | J7: 46237 | K7: 46248 | L7: 未開始 | M7: 0 | N7: =H7*M7 -> 0 | O7: 跨模組直接匯入會被 import-linter 擋下
A8: 1.7 | B8: S0 | C8: 環境與基礎建設 | D8: 基礎建設 | E8: 可觀測性基礎 | F8: OpenTelemetry trace／metrics／structured log，全部帶 tenant_id 標籤 | G8: DevOps | H8: 3 | I8: 1.6 | J8: 46237 | K8: 46248 | L8: 未開始 | M8: 0 | N8: =H8*M8 -> 0 | O8: 任一請求可依 request_id 追出完整 span
A9: 1.8 | B9: S0 | C9: 環境與基礎建設 | D9: 基礎建設 | E9: 密鑰管理接入 | F9: Secret Manager；資料庫僅存 *_ref 參照 | G9: DevOps | H9: 2 | I9: 1.3 | J9: 46237 | K9: 46248 | L9: 未開始 | M9: 0 | N9: =H9*M9 -> 0 | O9: Schema 檢查無明文密鑰欄位
A10: 1.9 | B10: S0 | C10: 環境與基礎建設 | D10: 專案管理 | E10: 規格評審與 WBS 基準確認 | F10: 規格書 v1.0 評審、估算校準、風險登錄 | G10: PM | H10: 2 | J10: 46237 | K10: 46248 | L10: 未開始 | M10: 0 | N10: =H10*M10 -> 0 | O10: 評審意見全部結案或轉為工作項
A11: 2.1 | B11: S1 | C11: 核心地基與租戶隔離 | D11: 核心地基 | E11: 套用 001_foundation 並驗證 | F11: extensions、set_context、觸發器、tenants／organizations／facilities | G11: DBA / Data | H11: 2 | I11: 1.4 | J11: 46251 | K11: 46262 | L11: 未開始 | M11: 0 | N11: =H11*M11 -> 0 | O11: 乾淨庫執行零錯誤
A12: 2.2 | B12: S1 | C12: 核心地基與租戶隔離 | D12: 核心地基 | E12: RLS 中介層（連線層強制） | F12: 連線取得後即執行 set_context；交易級 SET LOCAL | G12: Tech Lead | H12: 3 | I12: 1.6;2.1 | J12: 46251 | K12: 46262 | L12: 未開始 | M12: 0 | N12: =H12*M12 -> 0 | O12: 未設 context 的查詢回 0 列（CI 測試）
A13: 2.3 | B13: S1 | C13: 核心地基與租戶隔離 | D13: 核心地基 | E13: 套用 007_rls_policies 並驗證 | F13: 全表 RLS + FORCE RLS；平台目錄雙政策；審計表撤銷 UPDATE/DELETE | G13: DBA / Data | H13: 2.5 | I13: 2.1 | J13: 46251 | K13: 46262 | L13: 未開始 | M13: 0 | N13: =H13*M13 -> 0 | O13: T1 租戶隔離斷言通過
A14: 2.4 | B14: S1 | C14: 核心地基與租戶隔離 | D14: 核心地基 | E14: 租戶／組織／設施 CRUD API | F14: 含 ltree 子樹查詢（subtree_of）與父層搬移 | G14: Backend A | H14: 5 | I14: 2.2 | J14: 46251 | K14: 46262 | L14: 未開始 | M14: 0 | N14: =H14*M14 -> 0 | O14: 組織搬移後子樹 org_path 全部正確
A15: 2.5 | B15: S1 | C15: 核心地基與租戶隔離 | D15: 核心地基 | E15: 動態屬性驗證器 | F15: attribute_definitions → JSON Schema 驗證管線 | G15: Backend C | H15: 3 | I15: 2.2 | J15: 46251 | K15: 46262 | L15: 未開始 | M15: 0 | N15: =H15*M15 -> 0 | O15: 違規屬性回 422 並指出 JSON Pointer
A16: 2.6 | B16: S1 | C16: 核心地基與租戶隔離 | D16: 核心地基 | E16: 稽核日誌攔截器 | F16: 寫入 audit_log（before/after/diff_keys/request_id/ip） | G16: Backend D | H16: 3 | I16: 2.2 | J16: 46251 | K16: 46262 | L16: 未開始 | M16: 0 | N16: =H16*M16 -> 0 | O16: 所有寫入 API 皆產生稽核列
A17: 2.7 | B17: S1 | C17: 核心地基與租戶隔離 | D17: 核心地基 | E17: outbox 與 emit_event 機制 | F17: emit_event() + relay worker（FOR UPDATE SKIP LOCKED）+ 指數退避 | G17: Backend B | H17: 4 | I17: 2.2 | J17: 46251 | K17: 46262 | L17: 未開始 | M17: 0 | N17: =H17*M17 -> 0 | O17: 關閉 worker 後事件不遺失，重啟後補送
A18: 2.8 | B18: S1 | C18: 核心地基與租戶隔離 | D18: 核心地基 | E18: 冪等中介層 | F18: idempotency_keys；同鍵回放、進行中回 409、不同 body 回 422 | G18: Backend C | H18: 2.5 | I18: 2.2 | J18: 46251 | K18: 46262 | L18: 未開始 | M18: 0 | N18: =H18*M18 -> 0 | O18: 重複 POST 只產生一筆資料
A19: 2.9 | B19: S1 | C19: 核心地基與租戶隔離 | D19: 核心地基 | E19: API 共用層 | F19: cursor 分頁、排序、稀疏欄位、include 白名單、ETag/If-Match | G19: Tech Lead | H19: 4 | I19: 1.6 | J19: 46251 | K19: 46262 | L19: 未開始 | M19: 0 | N19: =H19*M19 -> 0 | O19: 任兩個資源的分頁與錯誤格式完全一致
A20: 2.10 | B20: S1 | C20: 核心地基與租戶隔離 | D20: 品質 | E20: 租戶隔離測試套件 | F20: 含未設 context、跨租戶讀寫、平台情境三類案例 | G20: QA | H20: 3 | I20: 2.3 | J20: 46251 | K20: 46262 | L20: 未開始 | M20: 0 | N20: =H20*M20 -> 0 | O20: 納入 CI 每次執行
A21: 3.1 | B21: S2 | C21: 身分整合與 RBAC | D21: 身分 | E21: 套用 002_identity 並驗證 | F21: 13 張表 + v_user_effective_permissions + 兩個判定函式 | G21: DBA / Data | H21: 2 | I21: 2.1 | J21: 46265 | K21: 46276 | L21: 未開始 | M21: 0 | N21: =H21*M21 -> 0 | O21: user_has_permission 於 ORG 範圍正確涵蓋子樹
A22: 3.2 | B22: S2 | C22: 身分整合與 RBAC | D22: 身分 | E22: 本地帳號認證 | F22: argon2id、密碼政策、失敗鎖定、auth_events | G22: Backend A | H22: 3 | I22: 3.1 | J22: 46265 | K22: 46276 | L22: 未開始 | M22: 0 | N22: =H22*M22 -> 0 | O22: 暴力破解測試觸發鎖定
... A63: 6.9 | B63: S5 | C63: Soft FM 與預防性維護 | D63: 品質 | E63: Soft FM 與 PM 測試 | F63: 動態表單驗證、RRULE 邊界、計量觸發 | G63: QA | H63: 4 | I63: 6.7 | J63: 46307 | K63: 46318 | L63: 未開始 | M63: 0 | N63: =H63*M63 -> 0 | O63: 覆蓋率 ≥ 90%
A64: 6.10 | B64: S5 | C64: Soft FM 與預防性維護 | D64: 專案管理 | E64: 期中檢視與範圍再確認 | F64: 進度、風險、開放問題結案狀況 | G64: PM | H64: 2 | J64: 46307 | K64: 46318 | L64: 未開始 | M64: 0 | N64: =H64*M64 -> 0 | O64: 里程碑 M5 通過
A65: 7.1 | B65: S6 | C65: 預約與附加服務連動 | D65: 預約 | E65: 套用 005_reservations 並驗證 | F65: 排他約束、hold 約束、availability 函式 | G65: DBA / Data | H65: 2.5 | I65: 2.1 | J65: 46321 | K65: 46332 | L65: 未開始 | M65: 0 | N65: =H65*M65 -> 0 | O65: T2 防重複預約斷言通過
A66: 7.2 | B66: S6 | C66: 預約與附加服務連動 | D66: 預約 | E66: 可預約資源設定 API | F66: 時段粒度、緩衝、capacity、報到與自動釋放規則 | G66: Backend C | H66: 4 | I66: 7.1;4.2 | J66: 46321 | K66: 46332 | L66: 未開始 | M66: 0 | N66: =H66*M66 -> 0 | O66: 共享池資源（capacity>1）行為正確
A67: 7.3 | B67: S6 | C67: 預約與附加服務連動 | D67: 預約 | E67: 可用時段查詢 API | F67: 多資源、忙碌區塊、free slots、封鎖與 hold 納入 | G67: Backend A | H67: 5 | I67: 7.2 | J67: 46321 | K67: 46332 | L67: 未開始 | M67: 0 | N67: =H67*M67 -> 0 | O67: 與排他約束結果完全一致（無假可用）
A68: 7.4 | B68: S6 | C68: 預約與附加服務連動 | D68: 預約 | E68: 兩階段 hold API | F68: 建立、消耗、釋放、過期 | G68: Backend A | H68: 3 | I68: 7.2 | J68: 46321 | K68: 46332 | L68: 未開始 | M68: 0 | N68: =H68*M68 -> 0 | O68: hold 期間他人無法預約同時段
A69: 7.5 | B69: S6 | C69: 預約與附加服務連動 | D69: 預約 | E69: 預約建立與變更 API | F69: 單一交易：驗證 → 消耗 hold → 寫入 → 附加服務 | G69: Backend B | H69: 5 | I69: 7.3;7.4 | J69: 46321 | K69: 46332 | L69: 未開始 | M69: 0 | N69: =H69*M69 -> 0 | O69: 併發搶訂測試恰好一筆成功
A70: 7.6 | B70: S6 | C70: 預約與附加服務連動 | D70: 預約 | E70: 週期預約 | F70: RRULE 展開、例外處理、系列取消 | G70: Backend D | H70: 4 | I70: 7.5 | J70: 46321 | K70: 46332 | L70: 未開始 | M70: 0 | N70: =H70*M70 -> 0 | O70: 部分時段衝突時回報清單而非全部失敗
A71: 7.7 | B71: S6 | C71: 預約與附加服務連動 | D71: 預約 | E71: 附加服務 fan-out worker | F71: reservation.confirmed → 建立服務工單並回填 | G71: Backend C | H71: 4 | I71: 7.5;6.2;2.7 | J71: 46321 | K71: 46332 | L71: 未開始 | M71: 0 | N71: =H71*M71 -> 0 | O71: 預約成功但建單失敗時可重試補齊
A72: 7.8 | B72: S6 | C72: 預約與附加服務連動 | D72: 預約 | E72: 報到與 reservation-janitor | F72: QR／人工報到、逾時 NO_SHOW、hold 過期清理 | G72: Backend D | H72: 4 | I72: 7.5 | J72: 46321 | K72: 46332 | L72: 未開始 | M72: 0 | N72: =H72*M72 -> 0 | O72: 未報到於設定時間後自動釋放
A73: 7.9 | B73: S6 | C73: 預約與附加服務連動 | D73: 預約 | E73: 封鎖時段與審核流程 | F73: blackouts、requires_approval 的審核與駁回 | G73: Backend B | H73: 3 | I73: 7.5 | J73: 46321 | K73: 46332 | L73: 未開始 | M73: 0 | N73: =H73*M73 -> 0 | O73: 封鎖時段內無法建立預約
A74: 7.10 | B74: S6 | C74: 預約與附加服務連動 | D74: 品質 | E74: 預約併發壓力測試 | F74: 100 執行緒搶同一時段；hold 競爭；半開區間邊界 | G74: QA | H74: 5 | I74: 7.8 | J74: 46321 | K74: 46332 | L74: 未開始 | M74: 0 | N74: =H74*M74 -> 0 | O74: 重複預約 0 筆
A75: 8.1 | B75: S7 | C75: IoT、告警與報表 | D75: IoT | E75: 套用 006 並驗證 | F75: 裝置、通訊點、分區、告警、ingest 與 raise_alarm 函式 | G75: DBA / Data | H75: 2.5 | I75: 2.1 | J75: 46335 | K75: 46346 | L75: 未開始 | M75: 0 | N75: =H75*M75 -> 0 | O75: T4 告警自動建單斷言通過
A76: 8.2 | B76: S7 | C76: IoT、告警與報表 | D76: IoT | E76: 裝置與通訊點 API | F76: 註冊、綁定設備／空間、通訊點對映計量 | G76: Backend C | H76: 4 | I76: 8.1;4.6 | J76: 46335 | K76: 46346 | L76: 未開始 | M76: 0 | N76: =H76*M76 -> 0 | O76: 裝置可綁定至既有設備並回寫 last_telemetry_at
... A134: 13.3 | B134: S12 | C134: AI、工作流程與最終驗收 | D134: 模組 | E134: 活動管理 | F134: 大型活動的多資源、多時段與人員配置 | G134: Backend B | H134: 6 | I134: 12.6 | J134: 46405 | K134: 46416 | L134: 未開始 | M134: 0 | N134: =H134*M134 -> 0 | O134: 一場活動可一次佔用多個空間並連動服務工單
A135: 13.4 | B135: S12 | C135: AI、工作流程與最終驗收 | D135: 用戶端 | E135: 天氣與外部小工具代理 | F135: 外部 API 代理與快取 | G135: Backend D | H135: 1 | J135: 46405 | K135: 46416 | L135: 未開始 | M135: 0 | N135: =H135*M135 -> 0 | O135: 外部服務失效時不影響主頁載入
A136: 13.5 | B136: S12 | C136: AI、工作流程與最終驗收 | D136: 品質 | E136: 全功能回歸測試 | F136: T1–T10 全綠、對照矩陣逐項覆核、非功能指標複測 | G136: QA | H136: 5 | I136: 13.3 | J136: 46405 | K136: 46416 | L136: 未開始 | M136: 0 | N136: =H136*M136 -> 0 | O136: 對照矩陣「011 後狀態」與實作一致
A137: 13.6 | B137: S12 | C137: AI、工作流程與最終驗收 | D137: 資安 | E137: 第二輪資安檢視 | F137: AI 查詢層與整合層的越權與注入測試 | G137: QA | H137: 3 | I137: 13.1 | J137: 46405 | K137: 46416 | L137: 未開始 | M137: 0 | N137: =H137*M137 -> 0 | O137: AI 查詢無法跨租戶取數
...

Sheet Sprint 摘要
A1: Sprint 摘要（全部欄位由 WBS 工作表計算）
A3: Sprint | B3: 階段主題 | C3: 開始 | D3: 結束 | E3: 工作日 | F3: 任務數 | G3: 估算(人日) | H3: 已完成(人日) | I3: 進度 | J3: 佔全期比重
A4: S0 | B4: 環境與基礎建設 | C4: 46237 | D4: 46248 | E4: =NETWORKDAYS(C4,D4) -> 10 | F4: =COUNTIF(WBS!$B$2:$B$138,A4) -> 9 | G4: =SUMIF(WBS!$B$2:$B$138,A4,WBS!$H$2:$H$138) -> 21.5 | H4: =SUMIF(WBS!$B$2:$B$138,A4,WBS!$N$2:$N$138) -> 0 | I4: =IFERROR(H4/G4,0) -> 0 | J4: =IFERROR(G4/$G$17,0) -> 0.043522267
A5: S1 | B5: 核心地基與租戶隔離 | C5: 46251 | D5: 46262 | E5: =NETWORKDAYS(C5,D5) -> 10 | F5: =COUNTIF(WBS!$B$2:$B$138,A5) -> 10 | G5: =SUMIF(WBS!$B$2:$B$138,A5,WBS!$H$2:$H$138) -> 32 | H5: =SUMIF(WBS!$B$2:$B$138,A5,WBS!$N$2:$N$138) -> 0 | I5: =IFERROR(H5/G5,0) -> 0 | J5: =IFERROR(G5/$G$17,0) -> 0.064777328
A6: S2 | B6: 身分整合與 RBAC | C6: 46265 | D6: 46276 | E6: =NETWORKDAYS(C6,D6) -> 10 | F6: =COUNTIF(WBS!$B$2:$B$138,A6) -> 12 | G6: =SUMIF(WBS!$B$2:$B$138,A6,WBS!$H$2:$H$138) -> 48 | H6: =SUMIF(WBS!$B$2:$B$138,A6,WBS!$N$2:$N$138) -> 0 | I6: =IFERROR(H6/G6,0) -> 0 | J6: =IFERROR(G6/$G$17,0) -> 0.097165992
A7: S3 | B7: 空間、BIM 與資產 | C7: 46279 | D7: 46290 | E7: =NETWORKDAYS(C7,D7) -> 10 | F7: =COUNTIF(WBS!$B$2:$B$138,A7) -> 11 | G7: =SUMIF(WBS!$B$2:$B$138,A7,WBS!$H$2:$H$138) -> 42 | H7: =SUMIF(WBS!$B$2:$B$138,A7,WBS!$N$2:$N$138) -> 0 | I7: =IFERROR(H7/G7,0) -> 0 | J7: =IFERROR(G7/$G$17,0) -> 0.085020243
A8: S4 | B8: 統一工單與狀態機 | C8: 46293 | D8: 46304 | E8: =NETWORKDAYS(C8,D8) -> 10 | F8: =COUNTIF(WBS!$B$2:$B$138,A8) -> 11 | G8: =SUMIF(WBS!$B$2:$B$138,A8,WBS!$H$2:$H$138) -> 46 | H8: =SUMIF(WBS!$B$2:$B$138,A8,WBS!$N$2:$N$138) -> 0 | I8: =IFERROR(H8/G8,0) -> 0 | J8: =IFERROR(G8/$G$17,0) -> 0.093117409
A9: S5 | B9: Soft FM 與預防性維護 | C9: 46307 | D9: 46318 | E9: =NETWORKDAYS(C9,D9) -> 10 | F9: =COUNTIF(WBS!$B$2:$B$138,A9) -> 10 | G9: =SUMIF(WBS!$B$2:$B$138,A9,WBS!$H$2:$H$138) -> 35 | H9: =SUMIF(WBS!$B$2:$B$138,A9,WBS!$N$2:$N$138) -> 0 | I9: =IFERROR(H9/G9,0) -> 0 | J9: =IFERROR(G9/$G$17,0) -> 0.070850202
A10: S6 | B10: 預約與附加服務連動 | C10: 46321 | D10: 46332 | E10: =NETWORKDAYS(C10,D10) -> 10 | F10: =COUNTIF(WBS!$B$2:$B$138,A10) -> 10 | G10: =SUMIF(WBS!$B$2:$B$138,A10,WBS!$H$2:$H$138) -> 39.5 | H10: =SUMIF(WBS!$B$2:$B$138,A10,WBS!$N$2:$N$138) -> 0 | I10: =IFERROR(H10/G10,0) -> 0 | J10: =IFERROR(G10/$G$17,0) -> 0.079959514
A11: S7 | B11: IoT、告警與報表 | C11: 46335 | D11: 46346 | E11: =NETWORKDAYS(C11,D11) -> 10 | F11: =COUNTIF(WBS!$B$2:$B$138,A11) -> 12 | G11: =SUMIF(WBS!$B$2:$B$138,A11,WBS!$H$2:$H$138) -> 44 | H11: =SUMIF(WBS!$B$2:$B$138,A11,WBS!$N$2:$N$138) -> 0 | I11: =IFERROR(H11/G11,0) -> 0 | J11: =IFERROR(G11/$G$17,0) -> 0.089068826
A12: S8 | B12: 硬化、效能與 UAT | C12: 46349 | D12: 46360 | E12: =NETWORKDAYS(C12,D12) -> 10 | F12: =COUNTIF(WBS!$B$2:$B$138,A12) -> 12 | G12: =SUMIF(WBS!$B$2:$B$138,A12,WBS!$H$2:$H$138) -> 43.5 | H12: =SUMIF(WBS!$B$2:$B$138,A12,WBS!$N$2:$N$138) -> 0 | I12: =IFERROR(H12/G12,0) -> 0 | J12: =IFERROR(G12/$G$17,0) -> 0.08805668
A13: S9 | B13: 對標補強 A：合併房間與配額 | C13: 46363 | D13: 46374 | E13: =NETWORKDAYS(C13,D13) -> 10 | F13: =COUNTIF(WBS!$B$2:$B$138,A13) -> 15 | G13: =SUMIF(WBS!$B$2:$B$138,A13,WBS!$H$2:$H$138) -> 36.5 | H13: =SUMIF(WBS!$B$2:$B$138,A13,WBS!$N$2:$N$138) -> 0 | I13: =IFERROR(H13/G13,0) -> 0 | J13: =IFERROR(G13/$G$17,0) -> 0.07388664
A14: S10 | B14: 對標補強 B：訪客與整合 | C14: 46377 | D14: 46388 | E14: =NETWORKDAYS(C14,D14) -> 10 | F14: =COUNTIF(WBS!$B$2:$B$138,A14) -> 10 | G14: =SUMIF(WBS!$B$2:$B$138,A14,WBS!$H$2:$H$138) -> 44.5 | H14: =SUMIF(WBS!$B$2:$B$138,A14,WBS!$N$2:$N$138) -> 0 | I14: =IFERROR(H14/G14,0) -> 0 | J14: =IFERROR(G14/$G$17,0) -> 0.090080972
A15: S11 | B15: 整合完備：多視訊平台與行事曆 | C15: 46391 | D15: 46402 | E15: =NETWORKDAYS(C15,D15) -> 10 | F15: =COUNTIF(WBS!$B$2:$B$138,A15) -> 8 | G15: =SUMIF(WBS!$B$2:$B$138,A15,WBS!$H$2:$H$138) -> 31.5 | H15: =SUMIF(WBS!$B$2:$B$138,A15,WBS!$N$2:$N$138) -> 0 | I15: =IFERROR(H15/G15,0) -> 0 | J15: =IFERROR(G15/$G$17,0) -> 0.063765182
A16: S12 | B16: AI、工作流程與最終驗收 | C16: 46405 | D16: 46416 | E16: =NETWORKDAYS(C16,D16) -> 10 | F16: =COUNTIF(WBS!$B$2:$B$138,A16) -> 7 | G16: =SUMIF(WBS!$B$2:$B$138,A16,WBS!$H$2:$H$138) -> 30 | H16: =SUMIF(WBS!$B$2:$B$138,A16,WBS!$N$2:$N$138) -> 0 | I16: =IFERROR(H16/G16,0) -> 0 | J16: =IFERROR(G16/$G$17,0) -> 0.060728745
B17: 合計 | E17: =SUM(E4:E16) -> 130 | F17: =SUM(F4:F16) -> 137 | G17: =SUM(G4:G16) -> 494 | H17: =SUM(H4:H16) -> 0 | I17: =IFERROR(H17/G17,0) -> 0
A19: 註：工作日以 NETWORKDAYS 計算，未扣除國定假日；估算為淨開發工時，不含跨團隊等待。

Sheet 資源負載
A1: 資源負載矩陣（角色 × Sprint，單位：人日）
A3: 角色 | B3: S0 | C3: S1 | D3: S2 | E3: S3 | F3: S4 | G3: S5 | H3: S6 | I3: S7 | J3: S8 | K3: S9 | L3: S10 | M3: S11 | N3: S12 | O3: 合計 | P3: 投入比例 | Q3: 可用產能 | R3: 負載率
A4: Tech Lead | B4: =SUMIFS(WBS!$H$2:$H$138,WBS!$G$2:$G$138,$A4,WBS!$B$2:$B$138,B$3) -> 3 | C4: =SUMIFS(WBS!$H$2:$H$138,WBS!$G$2:$G$138,$A4,WBS!$B$2:$B$138,C$3) -> 7 | D4: =SUMIFS(WBS!$H$2:$H$138,WBS!$G$2:$G$138,$A4,WBS!$B$2:$B$138,D$3) -> 4 | E4: =SUMIFS(WBS!$H$2:$H$138,WBS!$G$2:$G$138,$A4,WBS!$B$2:$B$138,E$3) -> 0 | F4: =SUMIFS(WBS!$H$2:$H$138,WBS!$G$2:$G$138,$A4,WBS!$B$2:$B$138,F$3) -> 6 | G4: =SUMIFS(WBS!$H$2:$H$138,WBS!$G$2:$G$138,$A4,WBS!$B$2:$B$138,G$3) -> 0 | H4: =SUMIFS(WBS!$H$2:$H$138,WBS!$G$2:$G$138,$A4,WBS!$B$2:$B$138,H$3) -> 0 | I4: =SUMIFS(WBS!$H$2:$H$138,WBS!$G$2:$G$138,$A4,WBS!$B$2:$B$138,I$3) -> 0 | ... N4: =SUMIFS(WBS!$H$2:$H$138,WBS!$G$2:$G$138,$A4,WBS!$B$2:$B$138,N$3) -> 0 | O4: =SUM(B4:N4) -> 31 | P4: =IFERROR(O4/$O$13,0) -> 0.062753036 | Q4: =$B$15*'Sprint 摘要'!$E$17*$B$25 -> 110.5 | R4: =IFERROR(O4/Q4,0) -> 0.28054299
A5: Backend A | B5: =SUMIFS(WBS!$H$2:$H$138,WBS!$G$2:$G$138,$A5,WBS!$B$2:$B$138,B$3) -> 0 | C5: =SUMIFS(WBS!$H$2:$H$138,WBS!$G$2:$G$138,$A5,WBS!$B$2:$B$138,C$3) -> 5 | D5: =SUMIFS(WBS!$H$2:$H$138,WBS!$G$2:$G$138,$A5,WBS!$B$2:$B$138,D$3) -> 9 | E5: =SUMIFS(WBS!$H$2:$H$138,WBS!$G$2:$G$138,$A5,WBS!$B$2:$B$138,E$3) -> 9 | F5: =SUMIFS(WBS!$H$2:$H$138,WBS!$G$2:$G$138,$A5,WBS!$B$2:$B$138,F$3) -> 8.5 | G5: =SUMIFS(WBS!$H$2:$H$138,WBS!$G$2:$G$138,$A5,WBS!$B$2:$B$138,G$3) -> 7.5 | H5: =SUMIFS(WBS!$H$2:$H$138,WBS!$G$2:$G$138,$A5,WBS!$B$2:$B$138,H$3) -> 8 | I5: =SUMIFS(WBS!$H$2:$H$138,WBS!$G$2:$G$138,$A5,WBS!$B$2:$B$138,I$3) -> 9 | ... N5: =SUMIFS(WBS!$H$2:$H$138,WBS!$G$2:$G$138,$A5,WBS!$B$2:$B$138,N$3) -> 8 | O5: =SUM(B5:N5) -> 93 | P5: =IFERROR(O5/$O$13,0) -> 0.18825911 | Q5: =$B$16*'Sprint 摘要'!$E$17*$B$25 -> 110.5 | R5: =IFERROR(O5/Q5,0) -> 0.84162896
A6: Backend B | B6: =SUMIFS(WBS!$H$2:$H$138,WBS!$G$2:$G$138,$A6,WBS!$B$2:$B$138,B$3) -> 0 | C6: =SUMIFS(WBS!$H$2:$H$138,WBS!$G$2:$G$138,$A6,WBS!$B$2:$B$138,C$3) -> 4 | D6: =SUMIFS(WBS!$H$2:$H$138,WBS!$G$2:$G$138,$A6,WBS!$B$2:$B$138,D$3) -> 9 | E6: =SUMIFS(WBS!$H$2:$H$138,WBS!$G$2:$G$138,$A6,WBS!$B$2:$B$138,E$3) -> 11 | F6: =SUMIFS(WBS!$H$2:$H$138,WBS!$G$2:$G$138,$A6,WBS!$B$2:$B$138,F$3) -> 8 | G6: =SUMIFS(WBS!$H$2:$H$138,WBS!$G$2:$G$138,$A6,WBS!$B$2:$B$138,G$3) -> 7.5 | H6: =SUMIFS(WBS!$H$2:$H$138,WBS!$G$2:$G$138,$A6,WBS!$B$2:$B$138,H$3) -> 8 | I6: =SUMIFS(WBS!$H$2:$H$138,WBS!$G$2:$G$138,$A6,WBS!$B$2:$B$138,I$3) -> 8 | ... N6: =SUMIFS(WBS!$H$2:$H$138,WBS!$G$2:$G$138,$A6,WBS!$B$2:$B$138,N$3) -> 6 | O6: =SUM(B6:N6) -> 91.5 | P6: =IFERROR(O6/$O$13,0) -> 0.18522267 | Q6: =$B$17*'Sprint 摘要'!$E$17*$B$25 -> 110.5 | R6: =IFERROR(O6/Q6,0) -> 0.8280543
A7: Backend C | B7: =SUMIFS(WBS!$H$2:$H$138,WBS!$G$2:$G$138,$A7,WBS!$B$2:$B$138,B$3) -> 0 | C7: =SUMIFS(WBS!$H$2:$H$138,WBS!$G$2:$G$138,$A7,WBS!$B$2:$B$138,C$3) -> 5.5 | D7: =SUMIFS(WBS!$H$2:$H$138,WBS!$G$2:$G$138,$A7,WBS!$B$2:$B$138,D$3) -> 9 | E7: =SUMIFS(WBS!$H$2:$H$138,WBS!$G$2:$G$138,$A7,WBS!$B$2:$B$138,E$3) -> 8 | F7: =SUMIFS(WBS!$H$2:$H$138,WBS!$G$2:$G$138,$A7,WBS!$B$2:$B$138,F$3) -> 8 | G7: =SUMIFS(WBS!$H$2:$H$138,WBS!$G$2:$G$138,$A7,WBS!$B$2:$B$138,G$3) -> 7 | H7: =SUMIFS(WBS!$H$2:$H$138,WBS!$G$2:$G$138,$A7,WBS!$B$2:$B$138,H$3) -> 8 | I7: =SUMIFS(WBS!$H$2:$H$138,WBS!$G$2:$G$138,$A7,WBS!$B$2:$B$138,I$3) -> 8 | ... N7: =SUMIFS(WBS!$H$2:$H$138,WBS!$G$2:$G$138,$A7,WBS!$B$2:$B$138,N$3) -> 4 | O7: =SUM(B7:N7) -> 84.5 | P7: =IFERROR(O7/$O$13,0) -> 0.17105263 | Q7: =$B$18*'Sprint 摘要'!$E$17*$B$25 -> 110.5 | R7: =IFERROR(O7/Q7,0) -> 0.76470588
A8: Backend D | B8: =SUMIFS(WBS!$H$2:$H$138,WBS!$G$2:$G$138,$A8,WBS!$B$2:$B$138,B$3) -> 0 | C8: =SUMIFS(WBS!$H$2:$H$138,WBS!$G$2:$G$138,$A8,WBS!$B$2:$B$138,C$3) -> 3 | D8: =SUMIFS(WBS!$H$2:$H$138,WBS!$G$2:$G$138,$A8,WBS!$B$2:$B$138,D$3) -> 8 | E8: =SUMIFS(WBS!$H$2:$H$138,WBS!$G$2:$G$138,$A8,WBS!$B$2:$B$138,E$3) -> 8 | F8: =SUMIFS(WBS!$H$2:$H$138,WBS!$G$2:$G$138,$A8,WBS!$B$2:$B$138,F$3) -> 8 | G8: =SUMIFS(WBS!$H$2:$H$138,WBS!$G$2:$G$138,$A8,WBS!$B$2:$B$138,G$3) -> 7 | H8: =SUMIFS(WBS!$H$2:$H$138,WBS!$G$2:$G$138,$A8,WBS!$B$2:$B$138,H$3) -> 8 | I8: =SUMIFS(WBS!$H$2:$H$138,WBS!$G$2:$G$138,$A8,WBS!$B$2:$B$138,I$3) -> 10 | ... N8: =SUMIFS(WBS!$H$2:$H$138,WBS!$G$2:$G$138,$A8,WBS!$B$2:$B$138,N$3) -> 1 | O8: =SUM(B8:N8) -> 77.5 | P8: =IFERROR(O8/$O$13,0) -> 0.15688259 | Q8: =$B$19*'Sprint 摘要'!$E$17*$B$25 -> 110.5 | R8: =IFERROR(O8/Q8,0) -> 0.70135747
A9: DBA / Data | B9: =SUMIFS(WBS!$H$2:$H$138,WBS!$G$2:$G$138,$A9,WBS!$B$2:$B$138,B$3) -> 2 | C9: =SUMIFS(WBS!$H$2:$H$138,WBS!$G$2:$G$138,$A9,WBS!$B$2:$B$138,C$3) -> 4.5 | D9: =SUMIFS(WBS!$H$2:$H$138,WBS!$G$2:$G$138,$A9,WBS!$B$2:$B$138,D$3) -> 2 | E9: =SUMIFS(WBS!$H$2:$H$138,WBS!$G$2:$G$138,$A9,WBS!$B$2:$B$138,E$3) -> 2 | F9: =SUMIFS(WBS!$H$2:$H$138,WBS!$G$2:$G$138,$A9,WBS!$B$2:$B$138,F$3) -> 2.5 | G9: =SUMIFS(WBS!$H$2:$H$138,WBS!$G$2:$G$138,$A9,WBS!$B$2:$B$138,G$3) -> 0 | H9: =SUMIFS(WBS!$H$2:$H$138,WBS!$G$2:$G$138,$A9,WBS!$B$2:$B$138,H$3) -> 2.5 | I9: =SUMIFS(WBS!$H$2:$H$138,WBS!$G$2:$G$138,$A9,WBS!$B$2:$B$138,I$3) -> 5 | ... N9: =SUMIFS(WBS!$H$2:$H$138,WBS!$G$2:$G$138,$A9,WBS!$B$2:$B$138,N$3) -> 0 | O9: =SUM(B9:N9) -> 22.5 | P9: =IFERROR(O9/$O$13,0) -> 0.045546559 | Q9: =$B$20*'Sprint 摘要'!$E$17*$B$25 -> 55.25 | R9: =IFERROR(O9/Q9,0) -> 0.40723982
A10: DevOps | B10: =SUMIFS(WBS!$H$2:$H$138,WBS!$G$2:$G$138,$A10,WBS!$B$2:$B$138,B$3) -> 14.5 | C10: =SUMIFS(WBS!$H$2:$H$138,WBS!$G$2:$G$138,$A10,WBS!$B$2:$B$138,C$3) -> 0 | D10: =SUMIFS(WBS!$H$2:$H$138,WBS!$G$2:$G$138,$A10,WBS!$B$2:$B$138,D$3) -> 3 | E10: =SUMIFS(WBS!$H$2:$H$138,WBS!$G$2:$G$138,$A10,WBS!$B$2:$B$138,E$3) -> 0 | F10: =SUMIFS(WBS!$H$2:$H$138,WBS!$G$2:$G$138,$A10,WBS!$B$2:$B$138,F$3) -> 0 | G10: =SUMIFS(WBS!$H$2:$H$138,WBS!$G$2:$G$138,$A10,WBS!$B$2:$B$138,G$3) -> 0 | H10: =SUMIFS(WBS!$H$2:$H$138,WBS!$G$2:$G$138,$A10,WBS!$B$2:$B$138,H$3) -> 0 | I10: =SUMIFS(WBS!$H$2:$H$138,WBS!$G$2:$G$138,$A10,WBS!$B$2:$B$138,I$3) -> 0 | ... N10: =SUMIFS(WBS!$H$2:$H$138,WBS!$G$2:$G$138,$A10,WBS!$B$2:$B$138,N$3) -> 0 | O10: =SUM(B10:N10) -> 30 | P10: =IFERROR(O10/$O$13,0) -> 0.060728745 | Q10: =$B$21*'Sprint 摘要'!$E$17*$B$25 -> 66.3 | R10: =IFERROR(O10/Q10,0) -> 0.45248869
A11: QA | B11: =SUMIFS(WBS!$H$2:$H$138,WBS!$G$2:$G$138,$A11,WBS!$B$2:$B$138,B$3) -> 0 | C11: =SUMIFS(WBS!$H$2:$H$138,WBS!$G$2:$G$138,$A11,WBS!$B$2:$B$138,C$3) -> 3 | D11: =SUMIFS(WBS!$H$2:$H$138,WBS!$G$2:$G$138,$A11,WBS!$B$2:$B$138,D$3) -> 4 | E11: =SUMIFS(WBS!$H$2:$H$138,WBS!$G$2:$G$138,$A11,WBS!$B$2:$B$138,E$3) -> 4 | F11: =SUMIFS(WBS!$H$2:$H$138,WBS!$G$2:$G$138,$A11,WBS!$B$2:$B$138,F$3) -> 5 | G11: =SUMIFS(WBS!$H$2:$H$138,WBS!$G$2:$G$138,$A11,WBS!$B$2:$B$138,G$3) -> 4 | H11: =SUMIFS(WBS!$H$2:$H$138,WBS!$G$2:$G$138,$A11,WBS!$B$2:$B$138,H$3) -> 5 | I11: =SUMIFS(WBS!$H$2:$H$138,WBS!$G$2:$G$138,$A11,WBS!$B$2:$B$138,I$3) -> 4 | ... N11: =SUMIFS(WBS!$H$2:$H$138,WBS!$G$2:$G$138,$A11,WBS!$B$2:$B$138,N$3) -> 8 | O11: =SUM(B11:N11) -> 51.5 | P11: =IFERROR(O11/$O$13,0) -> 0.10425101 | Q11: =$B$22*'Sprint 摘要'!$E$17*$B$25 -> 88.4 | R11: =IFERROR(O11/Q11,0) -> 0.58257919
A12: PM | B12: =SUMIFS(WBS!$H$2:$H$138,WBS!$G$2:$G$138,$A12,WBS!$B$2:$B$138,B$3) -> 2 | C12: =SUMIFS(WBS!$H$2:$H$138,WBS!$G$2:$G$138,$A12,WBS!$B$2:$B$138,C$3) -> 0 | D12: =SUMIFS(WBS!$H$2:$H$138,WBS!$G$2:$G$138,$A12,WBS!$B$2:$B$138,D$3) -> 0 | E12: =SUMIFS(WBS!$H$2:$H$138,WBS!$G$2:$G$138,$A12,WBS!$B$2:$B$138,E$3) -> 0 | F12: =SUMIFS(WBS!$H$2:$H$138,WBS!$G$2:$G$138,$A12,WBS!$B$2:$B$138,F$3) -> 0 | G12: =SUMIFS(WBS!$H$2:$H$138,WBS!$G$2:$G$138,$A12,WBS!$B$2:$B$138,G$3) -> 2 | H12: =SUMIFS(WBS!$H$2:$H$138,WBS!$G$2:$G$138,$A12,WBS!$B$2:$B$138,H$3) -> 0 | I12: =SUMIFS(WBS!$H$2:$H$138,WBS!$G$2:$G$138,$A12,WBS!$B$2:$B$138,I$3) -> 0 | ... N12: =SUMIFS(WBS!$H$2:$H$138,WBS!$G$2:$G$138,$A12,WBS!$B$2:$B$138,N$3) -> 3 | O12: =SUM(B12:N12) -> 12.5 | P12: =IFERROR(O12/$O$13,0) -> 0.025303644 | Q12: =$B$23*'Sprint 摘要'!$E$17*$B$25 -> 33.15 | R12: =IFERROR(O12/Q12,0) -> 0.37707391
A13: 合計 | B13: =SUM(B4:B12) -> 21.5 | C13: =SUM(C4:C12) -> 32 | D13: =SUM(D4:D12) -> 48 | E13: =SUM(E4:E12) -> 42 | F13: =SUM(F4:F12) -> 46 | G13: =SUM(G4:G12) -> 35 | H13: =SUM(H4:H12) -> 39.5 | I13: =SUM(I4:I12) -> 44 | ... O13: =SUM(O4:O12) -> 494
A14: 人力配置假設（FTE，可調整）
A15: Tech Lead | B15: 1 | C15: FTE（1.0 = 全職投入）
A16: Backend A | B16: 1 | C16: FTE（1.0 = 全職投入）
A17: Backend B | B17: 1 | C17: FTE（1.0 = 全職投入）
A18: Backend C | B18: 1 | C18: FTE（1.0 = 全職投入）
A19: Backend D | B19: 1 | C19: FTE（1.0 = 全職投入）
A20: DBA / Data | B20: 0.5 | C20: FTE（1.0 = 全職投入）
A21: DevOps | B21: 0.6 | C21: FTE（1.0 = 全職投入）
A22: QA | B22: 0.8 | C22: FTE（1.0 = 全職投入）
A23: PM | B23: 0.3 | C23: FTE（1.0 = 全職投入）
A24: 合計 FTE | B24: =SUM(B15:B23) -> 7.2
A25: 有效投入率 | B25: 0.85 | C25: 扣除會議、支援與context switch 後的實際可投入比例
A27: 註：可用產能 = FTE × 全期工作日 × 有效投入率；負載率超過 100% 表示該角色需增補人力或調整範圍。

Sheet 里程碑
A1: 里程碑與通過條件（Gate Criteria）
A3: 里程碑 | B3: 名稱 | C3: 目標日期 | D3: 對應 Sprint | E3: 通過條件（全部滿足才算通過） | F3: 相關 WBS | G3: 狀態
A4: M1 | B4: 環境與骨架就緒 | C4: 46248 | D4: S0 | E4: CI 全綠；dev/staging 可一鍵套用 migration；fms_app 角色確認無 BYPASSRLS；trace 可依 request_id 追出完整鏈路 | F4: 1.1–1.9 | G4: 未開始
A5: M2 | B5: 租戶隔離驗證通過 | C5: 46262 | D5: S1 | E5: T1 隔離斷言通過；未設 context 的查詢回 0 列（CI 強制）；outbox 關閉 worker 後事件不遺失；分頁與錯誤格式一致性檢查通過 | F5: 2.1–2.10 | G5: 未開始
A6: M3 | B6: 混合式 AD 可登入 | C6: 46276 | D6: S2 | E6: Entra ID、地端 AD、本地帳號三軌皆可登入；一次 FULL + 一次 DELTA 同步完成；人工指派授權未被同步影響 | F6: 3.1–3.12 | G6: 未開始
A7: M4 | B7: 空間與資產可用 | C7: 46290 | D7: S3 | E7: 1 萬節點 tree 查詢 P95 < 500 ms；2 萬設備列表 P95 < 300 ms；BIM 未識別元件可人工對應；Lovable 資產匯入差異報告經客戶確認 | F7: 4.1–4.11 | G7: 未開始
A8: M5 | B8: 工單與 SLA 上線 | C8: 46304 | D8: S4 | E8: T3 狀態機斷言通過；狀態機路徑覆蓋 100%；逾期案件 1 分鐘內標記；available-actions 可驅動前端按鈕 | F8: 5.1–5.11 | G8: 未開始
A9: M6 | B9: Soft FM 與 PM 可用 | C9: 46318 | D9: S5 | E9: 動態表單驗證回報 JSON Pointer；pm-generator 重跑不重複產單；PM 合規率與人工抽樣一致 | F9: 6.1–6.10 | G9: 未開始
A10: M7 | B10: 預約併發驗證通過 | C10: 46332 | D10: S6 | E10: T2 斷言通過；100 執行緒搶訂恰好一筆成功；附加服務 fan-out 可重試補齊；未報到自動釋放 | F10: 7.1–7.10 | G10: 未開始
A11: M8 | B11: 核心功能交付（對標補強前） | C11: 46360 | D11: S7–S8 | E11: T4 斷言通過；23 筆孤兒告警補串完成；全部 NFR 效能目標達成；資安高風險項全部修復；TS client 跑通端到端流程；PITR 演練達 RPO/RTO；上線檢查表全數通過 | F11: 8.1–9.11 | G11: 未開始
A12: M9 | B12: Offision 功能對標達成 | C12: 46388 | D12: S9–S10 | E12: 012 煙霧測試 T5–T10 全部通過；合併房間雙向互斥經併發測試驗證；配額硬上限正確拒絕；訪客 QR 報到與門禁開門全鏈路可回溯；Teams 連結自動建立；面板即場預約可用 | F12: 10.1–11.8 | G12: 未開始
A13: M10 | B13: 全功能交付（含全部 P2） | C13: 46416 | D13: S11–S12 | E13: 四家視訊平台連結皆可建立；行事曆雙向同步含衝突處理；AI 查詢受白名單與 RLS 雙重約束且無法跨租戶；活動管理可一次佔用多空間；T1–T10 全綠；對照矩陣逐項覆核一致；第二輪資安檢視無高風險項 | F13: 12.1–13.7 | G13: 未開始

Sheet 假設與風險
A1: 估算假設、人力配置與主要風險
A3: 估算假設
B5: 估算單位 | C5: 人日（8 小時）；為淨開發工時，不含跨團隊等待與客戶回覆時間
B6: 開發環境 | C6: 自建 PostgreSQL 16（Docker Compose：PG＋Redis＋MinIO＋Mailpit＋MQTT），不使用託管服務；staging／production 為專用主機或 VM
B7: 範圍決策 | C7: 客戶決定延長時程以保後台功能完整，不砍 P2。原 21 人日的延後項目（Meet／Zoom／Webex、行事曆雙向同步、AI 查詢）已全部納入 S11–S12
B8: Sprint 長度 | C8: 2 週 = 10 個工作日；未扣除國定假日，排程時需再校準
B9: 團隊規模 | C9: 合計約 4.8 FTE（詳見「資源負載」工作表下方可調整的 FTE 假設）
B10: 估算方式 | C10: 以類比估算為主；資料庫與 API 任務已含單元測試與 code review 時間
B11: 緩衝 | C11: 各 Sprint 未內含緩衝；建議以 S8 硬化階段吸收前期溢出，或整體加 15% 管理緩衝
B12: QA 佔比偏低 | C12: QA 任務約佔總量 9%，低於常見的 15–20%。此估算假設開發者自行完成單元測試，QA 專注整合與非功能測試；若客戶要求較深的測試深度，需上調此比例
B13: 後端人力調整 | C13: 對標補強使後端工作量達 298 人日；3 名後端會全部超載 105% 以上，因此配置為 4 名（負載約 80%）。若僅能配置 3 名，需將 S9–S10 延長一個 Sprint
B14: 外部依賴 | C14: 客戶 AD／Entra 測試環境的取得時間不在估算內（見風險 R1）
B15: 不含項目 | C15: 前端／BFF 開發、Rust 引擎、Kafka、資料倉、行動端（屬第二～四階段）
B16: 對標延後項目 | C16: Google Meet／Zoom／Webex 連接器（7 人日）、外部行事曆雙向同步（6 人日）、AI 自然語言查詢（8 人日）已排入第二／三階段，不計入本 WBS
A19: 主要風險
A21: 編號 | B21: 風險 | C21: 影響 | D21: 機率 | E21: 應對與負責角色
A22: R1 | B22: 客戶 AD／Entra 測試環境取得延遲 | C22: S2 身分整合無法驗證，連帶影響 M3 | D22: 高 | E22: S0 即發出環境需求；先以自架 AD + Entra 開發者租戶開發（WBS 3.11）— PM／DevOps
A23: R2 | B23: RLS context 在新增資料存取路徑時被遺漏 | C23: 跨租戶資料洩漏 | D23: 中 | E23: 在連線層強制注入而非 API 層；CI 加入「未設 context 回 0 列」測試（WBS 2.2、2.10）— Tech Lead
A24: R3 | B24: Lovable 既有資料品質（47 筆待確認、B1 未識別設備） | C24: 上線後資料不可信，需重新匯入 | D24: 高 | E24: 匯入一律先跑試跑模式並產出差異報告；未識別項目不得以猜測值填入（WBS 4.10）— Backend A
A25: R4 | B25: 預約併發在真實負載下出現大量衝突重試 | C25: 使用者體驗差、資料庫負載升高 | D25: 中 | E25: S6 即進行 100 執行緒壓測；必要時提前導入第二階段 Redis 前置鎖（WBS 7.10）— QA／Tech Lead
A26: R5 | B26: 狀態機 side_effects 與實作不同步 | C26: 動作可執行但副作用未觸發 | D26: 中 | E26: 每個 side_effects 鍵都需有對應處理器與單元測試（WBS 5.2、5.11）— Tech Lead
A27: R6 | B27: 遙測資料量超出第一階段假設 | C27: 查詢變慢、儲存成本上升 | D27: 中 | E27: 寫入已封裝於 ingest_telemetry()；達門檻改用 TimescaleDB 或第四階段 Rust broker（WBS 8.11）— DBA
A28: R7 | B28: 客戶 UAT 期間需求擴張 | C28: 時程延誤、第一階段無法收斂 | D28: 高 | E28: 以規格書第 2 章「範圍外」為依據；新需求一律登錄為第二階段候選（WBS 9.11）— PM
A29: R8 | B29: 單一資深人力（Tech Lead）成為瓶頸 | C29: 狀態機、權限、API 共用層集中於一人 | D29: 中 | E29: 關鍵設計以 pair review 與文件化擴散；FTE 假設保留 0.7 以維持審查頻寬 — PM
