Workbook

Sheet 說明
A1: Offision 功能對照矩陣 — Bizlution FMS 後端支援度分析
A3: 分析對象 | B3: Offision v4.5.4-20067（ONEs Software Limited）— 依《Offision功能參考文件.docx》逐條對照
A4: 對照基準 | B4: Bizlution FMS 第一階段後端（sql/001–012、api/openapi.yaml）
A5: 分析日期 | B5: 2026-07-29
A6: 功能項目數 | B6: ="共 "&COUNTA(對照矩陣!A2:A400)&" 項" -> 共 139 項
A7: 結論（011 補強前） | B7: ="完全支援或超越 "&TEXT(統計摘要!$D$6,"0%")&"；缺口 "&TEXT(統計摘要!$F$6,"0%") -> 完全支援或超越 55%；缺口 29%
A8: 結論（011 補強後） | B8: ="完全支援或超越 "&TEXT(統計摘要!$D$7,"0%")&"；剩餘缺口 "&TEXT(統計摘要!$F$7,"0%") -> 完全支援或超越 83%；剩餘缺口 4%
A9: 剩餘工作量 | B9: ="API／服務層 "&TEXT(對照矩陣!$K$141,"0.0")&" 人日（不含前端，另計 011 已完成的資料層）" -> API／服務層 160.0 人日（不含前端，另計 011 已完成的資料層）
A11: 工作表導覽
A12: 對照矩陣 | B12: 逐條功能對照：Offision 行為、011 前後支援狀態、對應資料表與 API、缺口與工作量
A13: 統計摘要 | B13: 依領域與狀態的交叉統計，以及補強前後的覆蓋率（全部為公式）
A14: 剩餘工作 | B14: 仍需實作的項目清單，含人日與優先級，可直接併入 WBS
A15: 參考來源 | B15: 文件與網路佐證來源
A17: 狀態定義
A18: 超越 | B18: 我方能力超出 Offision（例：資料庫層排他約束、無限層組織樹、資料驅動狀態機）
A19: 完全支援 | B19: 資料模型已完整支援，僅需一般 API／查詢實作
A20: 需補 API | B20: 資料模型足夠，但需補 API、設定或先與客戶確認定義（無需改 schema）
A21: 011 已補強 | B21: 原為缺口，已於 sql/011_offision_parity.sql 補上資料結構
A22: 缺口 | B22: 仍為缺口，需新增資料結構或外部整合
A23: 範圍外 | B23: 建議劃出 FMS 核心範圍（HR／財務／行銷領域）
A25: 使用說明
A26: 要你填的欄位 | B26: 「對照矩陣」L 欄（決策）與 M 欄（負責人）；黃色底色為輸入格
A27: 人日欄（K 欄） | B27: 藍色字為估算輸入值，改動後統計與剩餘工作會自動重算
A28: 重要提醒 | B28: 「範圍外」項目請於客戶簡報中明確標示，避免在 UAT 階段被視為缺漏

Sheet 對照矩陣
A1: 編號 | B1: Offision 章節 | C1: 領域 | D1: 功能項目 | E1: Offision 行為 | F1: 011 前狀態 | G1: 011 後狀態 | H1: 對應資料表／物件 | I1: 對應 API | J1: 缺口說明／待辦 | K1: 人日 | L1: 決策 | M1: 負責人
A2: 1 | B2: §1.2 | C2: 架構 | D2: 多分支機構架構 | E2: HQ + 子分公司兩層，分部各自配置資源 | F2: 超越 | G2: 超越 | H2: tenants / organizations(ltree) / facilities | I2: GET /organizations?subtree_of | J2: 我方為無限層組織樹，集團→子公司→事業部→部門皆可 | K2: 0 | L2: 待決
A3: 2 | B3: §1.1 | C3: 架構 | D3: SaaS 多租戶 | E3: 雲端多租戶，無本地安裝 | F3: 超越 | G3: 超越 | H3: 全表 tenant_id + RLS + FORCE RLS | I3: — | J3: 隔離由資料庫引擎強制，非應用層條件 | K3: 0 | L3: 待決
A4: 3 | B4: §1.3 | C4: 權限 | D4: 角色型存取控制 | E4: 4 種角色：超管／分部管理員／維修人員／一般用戶 | F4: 超越 | G4: 超越 | H4: roles / permissions / user_role_assignments | I4: POST /users/{id}/role-assignments | J4: 我方 11 系統角色、84 權限、四層 scope（可授權到單一樓層） | K4: 0 | L4: 待決
A5: 4 | B5: §1.1 | C5: 權限 | D5: 多語言 | E5: 繁中／英文 | F5: 需補 API | G5: 需補 API | H5: notification_templates.locale / users.locale / amenities.name_en | I5: — | J5: API 需支援 Accept-Language 並回傳對應語系字典 | K5: 2 | L5: 待決
A6: 5 | B6: §2.1 | C6: 用戶端 | D6: 頁籤：所有（公告＋時間軸） | E6: 公告橫幅＋今日時間軸＋快速預約 | F6: 缺口 | G6: 011 已補強 | H6: announcements / reservations | I6: GET /announcements/feed | J6: 011 已補公告表；需 feed API 與橫幅邏輯 | K6: 2.5 | L6: 待決
A7: 6 | B7: §2.1 | C7: 用戶端 | D7: 頁籤：會議室 | E7: 預約房間、立即尋找、線上會議 | F7: 完全支援 | G7: 完全支援 | H7: bookable_resources(SPATIAL_NODE) | I7: GET /facilities/{id}/availability | K7: 0 | L7: 待決
A8: 7 | B8: §2.1 | C8: 用戶端 | D8: 頁籤：辦公桌 | E8: 預約辦公桌、立即尋找 | F8: 完全支援 | G8: 完全支援 | H8: spatial_node_types(DESK) / bookable_resources | I8: 同上 | J8: 節點型別已含 DESK、DESK_AREA | K8: 0 | L8: 待決
A9: 8 | B9: §2.1 | C9: 用戶端 | D9: 頁籤：設備 | E9: 預約共用設備（投影機、相機） | F9: 完全支援 | G9: 完全支援 | H9: bookable_resources(resource_type=ASSET) | I9: 同上 | J9: 設備預約以 ASSET 型資源實作 | K9: 0 | L9: 待決
A10: 9 | B10: §2.1 | C10: 用戶端 | D10: 頁籤：停車位 | E10: 預約停車位 | F10: 完全支援 | G10: 完全支援 | H10: spatial_node_types(PARKING_SPACE) | I10: 同上 | K10: 0 | L10: 待決
A11: 10 | B11: §2.1 | C11: 用戶端 | D11: 頁籤：其他資源 | E11: 自定義可預約資源 | F11: 完全支援 | G11: 完全支援 | H11: spatial_node_types(租戶可擴充) | I11: POST /spatial-node-types | K11: 0 | L11: 待決
A12: 11 | B12: §2.1 | C12: 用戶端 | D12: 頁籤：訪客 | E12: 邀請訪客、訪客預登記 | F12: 缺口 | G12: 011 已補強 | H12: visitors / visitor_invitations / visitor_access_grants | I12: POST /visitor-invitations | J12: 011 已補三張表；需邀請、預登記、報到 API 與 QR 產生 | K12: 6 | L12: 待決
A13: 12 | B13: §2.1 | C13: 用戶端 | D13: 頁籤：服務 | E13: 服務申請（依角色顯示不同操作） | F13: 超越 | G13: 超越 | H13: service_items(form_schema) / work_orders | I13: POST /work-orders | J13: 我方另有 SLA、派工、狀態機與滿意度 | K13: 0 | L13: 待決
A14: 13 | B14: §2.1 | C14: 用戶端 | D14: 頁籤：代訂 | E14: 代他人預約資源 | F14: 完全支援 | G14: 完全支援 | H14: reservations.on_behalf_of_id | I14: POST /reservations | J14: 需權限檢查：代訂者需具該 scope 的 reservation:create | K14: 0.5 | L14: 待決
A15: 14 | B15: §2.1 | C15: 用戶端 | D15: 頁籤：已報告問題 | E15: 回報問題（工單申請） | F15: 超越 | G15: 超越 | H15: work_orders(CORRECTIVE) | I15: POST /work-orders | K15: 0 | L15: 待決
A16: 15 | B16: §2.1 | C16: 用戶端 | D16: 頁籤：公告 | E16: 查看公告、標記為已讀 | F16: 缺口 | G16: 011 已補強 | H16: announcements / announcement_reads | I16: POST /announcements/{id}/read | J16: 011 已補；需已讀與確認 API | K16: 1.5 | L16: 待決
A17: 16 | B17: §2.2.1 | C17: 預約 | D17: 單次預約 | E17: 一次性預約 | F17: 完全支援 | G17: 完全支援 | H17: reservations | I17: POST /reservations | K17: 0 | L17: 待決
A18: 17 | B18: §2.2.1 | C18: 預約 | D18: 重複預約 | E18: 每日／每週（選星期）／每月（選日期）、每 N 期、結束日 | F18: 完全支援 | G18: 完全支援 | H18: reservations.recurrence_rule(RRULE) / recurrence_group_id | I18: POST /reservations | J18: 需 RRULE 展開器與部分衝突回報 | K18: 3 | L18: 待決
A19: 18 | B19: §2.2.1 | C19: 預約 | D19: 系列預約 | E19: 多場獨立場次，每場可指派不同場地 | F19: 完全支援 | G19: 完全支援 | H19: reservations 共用 recurrence_group_id | I19: POST /reservations | J19: 各場次為獨立列，resource_id 可不同 | K19: 1.5 | L19: 待決
A20: 19 | B20: §2.2.4 | C20: 預約 | D20: 系列：從檔案匯入場次 | E20: 上傳清單批量建立場次 | F20: 需補 API | G20: 需補 API | H20: reservations / idempotency_keys | I20: POST /reservations:import | J20: 需匯入解析、試跑與差異報告 | K20: 3 | L20: 待決
A21: 20 | B21: §2.2.4 | C21: 預約 | D21: 系列：跳過衝突 | E21: Skip conflicts 選項 | F21: 需補 API | G21: 需補 API | H21: check_resource_availability | I21: POST /reservations?on_conflict=skip | J21: API 旗標，逐場次判定後回報略過清單 | K21: 1 | L21: 待決
A22: 21 | B22: §2.2.2 | C22: 預約 | D22: 欄位：標題（必填） | E22: 預約名稱 | F22: 完全支援 | G22: 完全支援 | H22: reservations.title | I22: — | K22: 0 | L22: 待決
A23: 22 | B23: §2.2.2 | C23: 預約 | D23: 欄位：私人預約 | E23: 僅本人可見詳情 | F23: 缺口 | G23: 011 已補強 | H23: reservations.is_private | I23: GET /reservations（遮罩） | J23: 011 已補欄位；API 需對非授權者遮罩標題／與會者／備註 | K23: 1.5 | L23: 待決
A24: 23 | B24: §2.2.2 | C24: 預約 | D24: 欄位：全天 | E24: 不需指定時間 | F24: 缺口 | G24: 011 已補強 | H24: reservations.is_all_day | I24: — | J24: 011 已補欄位 | K24: 0.5 | L24: 待決
A25: 24 | B25: §2.2.2 | C25: 預約 | D25: 欄位：容納人數建議 | E25: 依人數推薦房間 | F25: 完全支援 | G25: 完全支援 | H25: bookable_resources.capacity / spatial_nodes.capacity | I25: GET availability?min_capacity | K25: 0.5 | L25: 待決
A26: 25 | B26: §2.2.2 | C26: 預約 | D26: 欄位：與會者（內部＋外部） | E26: 加入內部用戶或外部訪客 | F26: 完全支援 | G26: 完全支援 | H26: reservation_participants | I26: POST /reservations | J26: 支援 user_id 或 external_email | K26: 1 | L26: 待決
A27: 26 | B27: §2.2.2 | C27: 預約 | D27: 欄位：會議備註 | E27: 描述或備註 | F27: 完全支援 | G27: 完全支援 | H27: reservations.description / purpose | I27: — | J27: 011 補上 description | K27: 0 | L27: 待決
A28: 27 | B28: §2.2 | C28: 預約 | D28: 衝突檢測 | E28: 與現有預約自動碰撞檢測 | F28: 超越 | G28: 超越 | H28: EXCLUDE USING gist(tenant_id,resource_id,time_range) | I28: — | J28: 資料庫層排他約束，任何併發下皆正確 | K28: 0 | L28: 待決
A29: 28 | B29: §2.2 | C29: 預約 | D29: 兩階段佔位 | E29: （Offision 無明確對應） | F29: 超越 | G29: 超越 | H29: reservation_holds + GiST 排他 | I29: POST /reservations/holds | J29: 填表期間不被搶走 | K29: 0 | L29: 待決
A30: 29 | B30: §2.2 | C30: 預約 | D30: 編輯／刪除預約 | E30: 開始前可隨時修改 | F30: 完全支援 | G30: 完全支援 | H30: reservations(version 樂觀鎖) | I30: PATCH / DELETE /reservations/{id} | K30: 1 | L30: 待決
A31: 30 | B31: §2.3.1 | C31: 檢視 | D31: 主頁時間軸 | E31: 今日預約時間軸 | F31: 完全支援 | G31: 完全支援 | H31: reservations | I31: GET /reservations?from&to | K31: 1 | L31: 待決
A32: 31 | B32: §2.3.2 | C32: 檢視 | D32: 即時平面圖 | E32: 互動平面圖即時顯示使用狀態 | F32: 完全支援 | G32: 完全支援 | H32: spatial_nodes.geometry / floor_plan_attachment_id | I32: GET /facilities/{id}/floor-view | J32: 011 補上樓層圖檔關聯；需 floor-view 聚合 API | K32: 4 | L32: 待決
A33: 32 | B33: §2.3.2 | C33: 檢視 | D33: 地圖：樓層切換 | E33: 下拉選單切換樓層 | F33: 完全支援 | G33: 完全支援 | H33: spatial_nodes.floor_level / floor_label | I33: GET spatial-nodes?floor_level | J33: floor_level 為可排序整數（-1=B1） | K33: 0 | L33: 待決
A34: 33 | B34: §2.3.2 | C34: 檢視 | D34: 地圖：搜尋人／部門／資源 | E34: 高亮顯示搜尋結果 | F34: 需補 API | G34: 需補 API | H34: users(trgm) / organizations / spatial_nodes(trgm) | I34: GET /search?q= | J34: 需統一搜尋 API 聚合三類實體 | K34: 2.5 | L34: 待決
A35: 34 | B35: §2.3.2 | C35: 檢視 | D35: 地圖：容量篩選 | E35: 按容納人數篩選 | F35: 完全支援 | G35: 完全支援 | H35: bookable_resources.capacity | I35: GET availability?min_capacity | K35: 0 | L35: 待決
A36: 35 | B36: §2.3.2 | C36: 檢視 | D36: 地圖：設施篩選 | E36: 投影機／螢幕／Wi-Fi／視訊／電視／麥克風 | F36: 缺口 | G36: 011 已補強 | H36: amenities / resource_amenities | I36: GET availability?amenities= | J36: 011 已補字典與 join 表（含 24 項平台預設） | K36: 2 | L36: 待決
A37: 36 | B37: §2.3.2 | C37: 檢視 | D37: 地圖：時間滑桿 | E37: 查看未來時間點的使用狀態 | F37: 完全支援 | G37: 完全支援 | H37: check_resource_availability | I37: GET availability?at= | K37: 0.5 | L37: 待決
A38: 37 | B38: §2.3.2 | C38: 檢視 | D38: 地圖：狀態圖例 | E38: 可用／使用中／不可用 | F38: 完全支援 | G38: 完全支援 | H38: spatial_nodes.status / reservations | I38: GET floor-view | K38: 0 | L38: 待決
A39: 38 | B39: §2.3.3 | C39: 檢視 | D39: 資源搜尋器 | E39: 可用時段篩選、Grid/List、類型篩選 | F39: 完全支援 | G39: 完全支援 | H39: bookable_resources | I39: GET availability | K39: 2 | L39: 待決
A40: 39 | B40: §2.3.3 | C40: 檢視 | D40: 資源收藏 | E40: 只顯示已收藏的資源 | F40: 缺口 | G40: 011 已補強 | H40: user_favorites | I40: POST /users/me/favorites | J40: 011 已補表 | K40: 1 | L40: 待決
...

Sheet 統計摘要
A1: 覆蓋率統計（全部由對照矩陣計算）
A3: 整體覆蓋率
A5: 時點 | B5: 項目總數 | C5: 支援（含超越） | D5: 支援率 | E5: 缺口數 | F5: 缺口率 | G5: 需補 API | H5: 範圍外
A6: 011 補強前 | B6: =COUNTA(對照矩陣!$A$2:$A$140) -> 139 | C6: =COUNTIF(對照矩陣!$F$2:$F$140,"完全支援")+COUNTIF(對照矩陣!$F$2:$F$140,"超越")+COUNTIF(對照矩陣!$F$2:$F$140,"011 已補強") -> 77 | D6: =IFERROR(C6/B6,0) -> 0.55395683 | E6: =COUNTIF(對照矩陣!$F$2:$F$140,"缺口") -> 41 | F6: =IFERROR(E6/B6,0) -> 0.29496403 | G6: =COUNTIF(對照矩陣!$F$2:$F$140,"需補 API") -> 16 | H6: =COUNTIF(對照矩陣!$F$2:$F$140,"範圍外") -> 5
A7: 011 補強後 | B7: =COUNTA(對照矩陣!$A$2:$A$140) -> 139 | C7: =COUNTIF(對照矩陣!$G$2:$G$140,"完全支援")+COUNTIF(對照矩陣!$G$2:$G$140,"超越")+COUNTIF(對照矩陣!$G$2:$G$140,"011 已補強") -> 116 | D7: =IFERROR(C7/B7,0) -> 0.83453237 | E7: =COUNTIF(對照矩陣!$G$2:$G$140,"缺口") -> 5 | F7: =IFERROR(E7/B7,0) -> 0.035971223 | G7: =COUNTIF(對照矩陣!$G$2:$G$140,"需補 API") -> 13 | H7: =COUNTIF(對照矩陣!$G$2:$G$140,"範圍外") -> 5
A9: 依領域統計（011 補強後）
A11: 領域 | B11: 項目數 | C11: 超越 | D11: 完全支援 | E11: 需補 API | F11: 011 已補強 | G11: 缺口 | H11: 範圍外 | I11: 剩餘人日
A12: AI | B12: =COUNTIF(對照矩陣!$C$2:$C$140,$A12) -> 4 | C12: =COUNTIFS(對照矩陣!$C$2:$C$140,$A12,對照矩陣!$G$2:$G$140,"超越") -> 0 | D12: =COUNTIFS(對照矩陣!$C$2:$C$140,$A12,對照矩陣!$G$2:$G$140,"完全支援") -> 0 | E12: =COUNTIFS(對照矩陣!$C$2:$C$140,$A12,對照矩陣!$G$2:$G$140,"需補 API") -> 1 | F12: =COUNTIFS(對照矩陣!$C$2:$C$140,$A12,對照矩陣!$G$2:$G$140,"011 已補強") -> 0 | G12: =COUNTIFS(對照矩陣!$C$2:$C$140,$A12,對照矩陣!$G$2:$G$140,"缺口") -> 2 | H12: =COUNTIFS(對照矩陣!$C$2:$C$140,$A12,對照矩陣!$G$2:$G$140,"範圍外") -> 1 | I12: =SUMIF(對照矩陣!$C$2:$C$140,$A12,對照矩陣!$K$2:$K$140) -> 7
A13: IoT | B13: =COUNTIF(對照矩陣!$C$2:$C$140,$A13) -> 6 | C13: =COUNTIFS(對照矩陣!$C$2:$C$140,$A13,對照矩陣!$G$2:$G$140,"超越") -> 1 | D13: =COUNTIFS(對照矩陣!$C$2:$C$140,$A13,對照矩陣!$G$2:$G$140,"完全支援") -> 2 | E13: =COUNTIFS(對照矩陣!$C$2:$C$140,$A13,對照矩陣!$G$2:$G$140,"需補 API") -> 0 | F13: =COUNTIFS(對照矩陣!$C$2:$C$140,$A13,對照矩陣!$G$2:$G$140,"011 已補強") -> 3 | G13: =COUNTIFS(對照矩陣!$C$2:$C$140,$A13,對照矩陣!$G$2:$G$140,"缺口") -> 0 | H13: =COUNTIFS(對照矩陣!$C$2:$C$140,$A13,對照矩陣!$G$2:$G$140,"範圍外") -> 0 | I13: =SUMIF(對照矩陣!$C$2:$C$140,$A13,對照矩陣!$K$2:$K$140) -> 11
A14: 分析 | B14: =COUNTIF(對照矩陣!$C$2:$C$140,$A14) -> 21 | C14: =COUNTIFS(對照矩陣!$C$2:$C$140,$A14,對照矩陣!$G$2:$G$140,"超越") -> 1 | D14: =COUNTIFS(對照矩陣!$C$2:$C$140,$A14,對照矩陣!$G$2:$G$140,"完全支援") -> 13 | E14: =COUNTIFS(對照矩陣!$C$2:$C$140,$A14,對照矩陣!$G$2:$G$140,"需補 API") -> 4 | F14: =COUNTIFS(對照矩陣!$C$2:$C$140,$A14,對照矩陣!$G$2:$G$140,"011 已補強") -> 2 | G14: =COUNTIFS(對照矩陣!$C$2:$C$140,$A14,對照矩陣!$G$2:$G$140,"缺口") -> 1 | H14: =COUNTIFS(對照矩陣!$C$2:$C$140,$A14,對照矩陣!$G$2:$G$140,"範圍外") -> 0 | I14: =SUMIF(對照矩陣!$C$2:$C$140,$A14,對照矩陣!$K$2:$K$140) -> 28.5
A15: 帳號 | B15: =COUNTIF(對照矩陣!$C$2:$C$140,$A15) -> 8 | C15: =COUNTIFS(對照矩陣!$C$2:$C$140,$A15,對照矩陣!$G$2:$G$140,"超越") -> 0 | D15: =COUNTIFS(對照矩陣!$C$2:$C$140,$A15,對照矩陣!$G$2:$G$140,"完全支援") -> 2 | E15: =COUNTIFS(對照矩陣!$C$2:$C$140,$A15,對照矩陣!$G$2:$G$140,"需補 API") -> 0 | F15: =COUNTIFS(對照矩陣!$C$2:$C$140,$A15,對照矩陣!$G$2:$G$140,"011 已補強") -> 6 | G15: =COUNTIFS(對照矩陣!$C$2:$C$140,$A15,對照矩陣!$G$2:$G$140,"缺口") -> 0 | H15: =COUNTIFS(對照矩陣!$C$2:$C$140,$A15,對照矩陣!$G$2:$G$140,"範圍外") -> 0 | I15: =SUMIF(對照矩陣!$C$2:$C$140,$A15,對照矩陣!$K$2:$K$140) -> 5.5
A16: 整合 | B16: =COUNTIF(對照矩陣!$C$2:$C$140,$A16) -> 6 | C16: =COUNTIFS(對照矩陣!$C$2:$C$140,$A16,對照矩陣!$G$2:$G$140,"超越") -> 0 | D16: =COUNTIFS(對照矩陣!$C$2:$C$140,$A16,對照矩陣!$G$2:$G$140,"完全支援") -> 0 | E16: =COUNTIFS(對照矩陣!$C$2:$C$140,$A16,對照矩陣!$G$2:$G$140,"需補 API") -> 0 | F16: =COUNTIFS(對照矩陣!$C$2:$C$140,$A16,對照矩陣!$G$2:$G$140,"011 已補強") -> 6 | G16: =COUNTIFS(對照矩陣!$C$2:$C$140,$A16,對照矩陣!$G$2:$G$140,"缺口") -> 0 | H16: =COUNTIFS(對照矩陣!$C$2:$C$140,$A16,對照矩陣!$G$2:$G$140,"範圍外") -> 0 | I16: =SUMIF(對照矩陣!$C$2:$C$140,$A16,對照矩陣!$K$2:$K$140) -> 24.5
A17: 架構 | B17: =COUNTIF(對照矩陣!$C$2:$C$140,$A17) -> 2 | C17: =COUNTIFS(對照矩陣!$C$2:$C$140,$A17,對照矩陣!$G$2:$G$140,"超越") -> 2 | D17: =COUNTIFS(對照矩陣!$C$2:$C$140,$A17,對照矩陣!$G$2:$G$140,"完全支援") -> 0 | E17: =COUNTIFS(對照矩陣!$C$2:$C$140,$A17,對照矩陣!$G$2:$G$140,"需補 API") -> 0 | F17: =COUNTIFS(對照矩陣!$C$2:$C$140,$A17,對照矩陣!$G$2:$G$140,"011 已補強") -> 0 | G17: =COUNTIFS(對照矩陣!$C$2:$C$140,$A17,對照矩陣!$G$2:$G$140,"缺口") -> 0 | H17: =COUNTIFS(對照矩陣!$C$2:$C$140,$A17,對照矩陣!$G$2:$G$140,"範圍外") -> 0 | I17: =SUMIF(對照矩陣!$C$2:$C$140,$A17,對照矩陣!$K$2:$K$140) -> 0
A18: 模組 | B18: =COUNTIF(對照矩陣!$C$2:$C$140,$A18) -> 14 | C18: =COUNTIFS(對照矩陣!$C$2:$C$140,$A18,對照矩陣!$G$2:$G$140,"超越") -> 2 | D18: =COUNTIFS(對照矩陣!$C$2:$C$140,$A18,對照矩陣!$G$2:$G$140,"完全支援") -> 1 | E18: =COUNTIFS(對照矩陣!$C$2:$C$140,$A18,對照矩陣!$G$2:$G$140,"需補 API") -> 1 | F18: =COUNTIFS(對照矩陣!$C$2:$C$140,$A18,對照矩陣!$G$2:$G$140,"011 已補強") -> 5 | G18: =COUNTIFS(對照矩陣!$C$2:$C$140,$A18,對照矩陣!$G$2:$G$140,"缺口") -> 1 | H18: =COUNTIFS(對照矩陣!$C$2:$C$140,$A18,對照矩陣!$G$2:$G$140,"範圍外") -> 4 | I18: =SUMIF(對照矩陣!$C$2:$C$140,$A18,對照矩陣!$K$2:$K$140) -> 12
A19: 檢視 | B19: =COUNTIF(對照矩陣!$C$2:$C$140,$A19) -> 12 | C19: =COUNTIFS(對照矩陣!$C$2:$C$140,$A19,對照矩陣!$G$2:$G$140,"超越") -> 0 | D19: =COUNTIFS(對照矩陣!$C$2:$C$140,$A19,對照矩陣!$G$2:$G$140,"完全支援") -> 9 | E19: =COUNTIFS(對照矩陣!$C$2:$C$140,$A19,對照矩陣!$G$2:$G$140,"需補 API") -> 1 | F19: =COUNTIFS(對照矩陣!$C$2:$C$140,$A19,對照矩陣!$G$2:$G$140,"011 已補強") -> 2 | G19: =COUNTIFS(對照矩陣!$C$2:$C$140,$A19,對照矩陣!$G$2:$G$140,"缺口") -> 0 | H19: =COUNTIFS(對照矩陣!$C$2:$C$140,$A19,對照矩陣!$G$2:$G$140,"範圍外") -> 0 | I19: =SUMIF(對照矩陣!$C$2:$C$140,$A19,對照矩陣!$K$2:$K$140) -> 15
A20: 權限 | B20: =COUNTIF(對照矩陣!$C$2:$C$140,$A20) -> 2 | C20: =COUNTIFS(對照矩陣!$C$2:$C$140,$A20,對照矩陣!$G$2:$G$140,"超越") -> 1 | D20: =COUNTIFS(對照矩陣!$C$2:$C$140,$A20,對照矩陣!$G$2:$G$140,"完全支援") -> 0 | E20: =COUNTIFS(對照矩陣!$C$2:$C$140,$A20,對照矩陣!$G$2:$G$140,"需補 API") -> 1 | F20: =COUNTIFS(對照矩陣!$C$2:$C$140,$A20,對照矩陣!$G$2:$G$140,"011 已補強") -> 0 | G20: =COUNTIFS(對照矩陣!$C$2:$C$140,$A20,對照矩陣!$G$2:$G$140,"缺口") -> 0 | H20: =COUNTIFS(對照矩陣!$C$2:$C$140,$A20,對照矩陣!$G$2:$G$140,"範圍外") -> 0 | I20: =SUMIF(對照矩陣!$C$2:$C$140,$A20,對照矩陣!$K$2:$K$140) -> 2
A21: 用戶端 | B21: =COUNTIF(對照矩陣!$C$2:$C$140,$A21) -> 15 | C21: =COUNTIFS(對照矩陣!$C$2:$C$140,$A21,對照矩陣!$G$2:$G$140,"超越") -> 2 | D21: =COUNTIFS(對照矩陣!$C$2:$C$140,$A21,對照矩陣!$G$2:$G$140,"完全支援") -> 7 | E21: =COUNTIFS(對照矩陣!$C$2:$C$140,$A21,對照矩陣!$G$2:$G$140,"需補 API") -> 0 | F21: =COUNTIFS(對照矩陣!$C$2:$C$140,$A21,對照矩陣!$G$2:$G$140,"011 已補強") -> 5 | G21: =COUNTIFS(對照矩陣!$C$2:$C$140,$A21,對照矩陣!$G$2:$G$140,"缺口") -> 1 | H21: =COUNTIFS(對照矩陣!$C$2:$C$140,$A21,對照矩陣!$G$2:$G$140,"範圍外") -> 0 | I21: =SUMIF(對照矩陣!$C$2:$C$140,$A21,對照矩陣!$K$2:$K$140) -> 16.5
A22: 稽核 | B22: =COUNTIF(對照矩陣!$C$2:$C$140,$A22) -> 3 | C22: =COUNTIFS(對照矩陣!$C$2:$C$140,$A22,對照矩陣!$G$2:$G$140,"超越") -> 0 | D22: =COUNTIFS(對照矩陣!$C$2:$C$140,$A22,對照矩陣!$G$2:$G$140,"完全支援") -> 2 | E22: =COUNTIFS(對照矩陣!$C$2:$C$140,$A22,對照矩陣!$G$2:$G$140,"需補 API") -> 1 | F22: =COUNTIFS(對照矩陣!$C$2:$C$140,$A22,對照矩陣!$G$2:$G$140,"011 已補強") -> 0 | G22: =COUNTIFS(對照矩陣!$C$2:$C$140,$A22,對照矩陣!$G$2:$G$140,"缺口") -> 0 | H22: =COUNTIFS(對照矩陣!$C$2:$C$140,$A22,對照矩陣!$G$2:$G$140,"範圍外") -> 0 | I22: =SUMIF(對照矩陣!$C$2:$C$140,$A22,對照矩陣!$K$2:$K$140) -> 3
A23: 管理端 | B23: =COUNTIF(對照矩陣!$C$2:$C$140,$A23) -> 17 | C23: =COUNTIFS(對照矩陣!$C$2:$C$140,$A23,對照矩陣!$G$2:$G$140,"超越") -> 0 | D23: =COUNTIFS(對照矩陣!$C$2:$C$140,$A23,對照矩陣!$G$2:$G$140,"完全支援") -> 15 | E23: =COUNTIFS(對照矩陣!$C$2:$C$140,$A23,對照矩陣!$G$2:$G$140,"需補 API") -> 1 | F23: =COUNTIFS(對照矩陣!$C$2:$C$140,$A23,對照矩陣!$G$2:$G$140,"011 已補強") -> 1 | G23: =COUNTIFS(對照矩陣!$C$2:$C$140,$A23,對照矩陣!$G$2:$G$140,"缺口") -> 0 | H23: =COUNTIFS(對照矩陣!$C$2:$C$140,$A23,對照矩陣!$G$2:$G$140,"範圍外") -> 0 | I23: =SUMIF(對照矩陣!$C$2:$C$140,$A23,對照矩陣!$K$2:$K$140) -> 9.5
... A27: 預約 | B27: =COUNTIF(對照矩陣!$C$2:$C$140,$A27) -> 14 | C27: =COUNTIFS(對照矩陣!$C$2:$C$140,$A27,對照矩陣!$G$2:$G$140,"超越") -> 2 | D27: =COUNTIFS(對照矩陣!$C$2:$C$140,$A27,對照矩陣!$G$2:$G$140,"完全支援") -> 8 | E27: =COUNTIFS(對照矩陣!$C$2:$C$140,$A27,對照矩陣!$G$2:$G$140,"需補 API") -> 2 | F27: =COUNTIFS(對照矩陣!$C$2:$C$140,$A27,對照矩陣!$G$2:$G$140,"011 已補強") -> 2 | G27: =COUNTIFS(對照矩陣!$C$2:$C$140,$A27,對照矩陣!$G$2:$G$140,"缺口") -> 0 | H27: =COUNTIFS(對照矩陣!$C$2:$C$140,$A27,對照矩陣!$G$2:$G$140,"範圍外") -> 0 | I27: =SUMIF(對照矩陣!$C$2:$C$140,$A27,對照矩陣!$K$2:$K$140) -> 13
A28: 合計 | B28: =SUM(B12:B27) -> 139 | C28: =SUM(C12:C27) -> 12 | D28: =SUM(D12:D27) -> 65 | E28: =SUM(E12:E27) -> 13 | F28: =SUM(F12:F27) -> 39 | G28: =SUM(G12:G27) -> 5 | H28: =SUM(H12:H27) -> 5 | I28: =SUM(I12:I27) -> 160
A30: 註：「支援」含 完全支援／超越／011 已補強；剩餘人日僅計後端 API 與服務層，不含前端與 BFF。

Sheet 剩餘工作
A1: 仍需實作的項目（可直接併入 WBS）
A3: 優先級 | B3: 領域 | C3: 功能項目 | D3: 待辦內容 | E3: 人日 | F3: 建議階段 | G3: 對應 WBS
A4: P0 | B4: 資源 | C4: 合併房間（Combinable） | D4: 011 已補；雙向互斥由資料庫保證，並可連動隔板佈置服務工單 | E4: 4 | F4: 第一階段
A5: P0 | B5: 預約 | C5: 重複預約 | D5: 需 RRULE 展開器與部分衝突回報 | E5: 3 | F5: 第一階段
A6: P0 | B6: 檢視 | C6: 地圖：設施篩選 | D6: 011 已補字典與 join 表（含 24 項平台預設） | E6: 2 | F6: 第一階段
A7: P0 | B7: 檢視 | C7: 資源搜尋器 | D7: API／服務層實作 | E7: 2 | F7: 第一階段
A8: P0 | B8: 管理端 | C8: 預約審批佇列 | D8: 待審批期間仍佔用時段（正確行為） | E8: 2 | F8: 第一階段
A9: P0 | B9: 檢視 | C9: 資源日曆 | D9: API／服務層實作 | E9: 1.5 | F9: 第一階段
A10: P0 | B10: 管理端 | C10: KPI：資源使用率 | D10: 營業時間需自 operating_hours 推算 | E10: 1.5 | F10: 第一階段
A11: P0 | B11: 預約 | C11: 欄位：與會者（內部＋外部） | D11: 支援 user_id 或 external_email | E11: 1 | F11: 第一階段
A12: P0 | B12: 預約 | C12: 編輯／刪除預約 | D12: API／服務層實作 | E12: 1 | F12: 第一階段
A13: P0 | B13: 檢視 | C13: 主頁時間軸 | D13: API／服務層實作 | E13: 1 | F13: 第一階段
A14: P0 | B14: 用戶端 | C14: 通知（審批結果） | D14: API／服務層實作 | E14: 1 | F14: 第一階段
A15: P0 | B15: 稽核 | C15: 預約操作稽核日誌 | D15: 六欄位全對應；對 fms_app 撤銷 UPDATE／DELETE | E15: 1 | F15: 第一階段
... A82: P2 | B82: 分析 | C82: 排行榜前 10 名資源 | D82: API／服務層實作 | E82: 0.5 | F82: 第二／三階段
D83: 合計 | E83: =SUM(E4:E82) -> 160
A85: P0 = Offision 文件自評必備；P1 = 強烈建議；P2 = 競爭差異化或可延後。

Sheet 參考來源
A1: 參考來源
A3: 類型 | B3: 來源 | C3: 用途／佐證內容
A4: 內部文件 | B4: Offision功能參考文件.docx（Bizlution 內部整理，2026-07） | C4: 功能清單主要依據；平台版本 v4.5.4-20067
A5: 官方網站 | B5: https://offision.com/features | C5: 模組全覽：房間／桌位／訪客／服務／停車／標牌／平面圖／分析
A6: 官方網站 | B6: https://offision.com/us/scene/69 | C6: 合併房間：預約複合房間時自動封鎖個別房間 —— 佐證 011 的 shadow 預約設計
A7: 官方網站 | B7: https://offision.com/us/scene/10 | C7: 附加服務（餐飲、技術支援）與服務提供者自動通知
A8: 官方網站 | B8: https://offision.com/us/booking-panel | C8: 門外預約面板與現場預約
A9: 官方網站 | B9: https://offision.com/scene/21 | C9: 預約面板控制門禁 —— 佐證 device_commands 的必要性
A10: 官方網站 | B10: https://offision.com/visitor-management | C10: 訪客管理可逐棟啟用 —— 佐證 facilities.visitor_management_enabled
A11: 官方網站 | B11: https://offision.com/us/attendance | C11: 考勤模組（我方建議劃出範圍）
A12: 官方網站 | B12: https://ones.software/us/bookings-one/room-booking/features | C12: 報到機制、未報到自動釋放、設備篩選
A13: 第三方 | B13: https://www.capterra.com/p/10038369/Offision/ | C13: 定價：Swift US$1.99／用戶／月，Plus US$3.99／用戶／月，1 個月免費試用
A16: 註：定價為按人計費，與我方按場館／資源計費的模式不同，比價時需換算。
